Workbook

Sheet Read Me
A1: Lounge Eligibility Lookup Table - LHR Terminal 3
A2: Schedule-agnostic model for estimating lounge demand by tier
A4: Item | B4: Detail
A5: Purpose | B5: Estimate the share of passengers on a flight who are eligible for each BA lounge tier at Heathrow T3, without needing flight numbers, aircraft types or seat maps.
A6: How the model was built | B6: 1) Decomposed BA's published access rules into demand drivers (First cabin + card status -> Tier 1, BA Gold -> Tier 2, Club cabin + Silver -> Tier 3), with each passenger counted once at their highest tier. 2) Chose two schedule-agnostic grouping dimensions - Route Group (5 buckets) and Time Band (3 windows). 3) Set neutral baseline (assumption) rates per route group x tier, flexed by business intensity multipliers. 4) Reviewed the BA Summer Schedule dataset (10000 flights, LHR, Apr-Oct 2025) and assigned every flight to the same 15 categories. 5) Recalibrated: computed verified category rates from the schedule data (eligible pax / boarded pax at 85% load factor) - baseline assumptions ran +46% vs actual on a representative day, so the Recommended Lookup now uses verified rates. 6) Applied both models to a representative sample day with live SUMIFS formulas and compared against the dataset's actual TIER1/2/3_ELIGIBLE_PAX.
A7: How to use | B7: 1) Classify each flight in your future schedule by Route Group and Time Band. 2) Look up Tier 1/2/3 eligibility % on the 'Recommended Lookup' sheet (data-calibrated; the 'Lookup Table' sheet is the assumption baseline kept for transparency). 3) Multiply by boarded passengers. 4) Compare category/peak totals with lounge capacity.
A8: Representative sample | B8: 18 June 2025 - a full operating day at LHR covering all 4 schedule regions and all 3 time bands (44 flights, 10,471 seats, 8,901 passengers at 85% LF). The Schedule Sample sheet assigns each flight to a category, applies the recommended percentages and compares with the dataset's own eligible-pax counts.
A9: Schedule validation | B9: All 10,000 flights were grouped and aggregated: Europe & Domestic is the highest-eligibility group (25.1-25.5% of passengers) and long-haul groups cluster at 14.9-16.2%; within-group time-of-day spread is at most 1.1pp versus a 10.6pp spread between route groups - so route group is the dominant driver. Verified rates replace the baseline assumptions; time multipliers are effectively 1.00 in the recommended table.
A10: Grouping dimensions | B10: Route Group (5): Europe & Domestic, North America, Asia & Oceania, Middle East & Africa, South America. Time Band (3): Early morning 05:00-09:59, Midday 10:00-15:59, Evening 16:00-22:59 (mapped from the dataset's 4 TIME_OF_DAY values by clock time).
A11: Tier definitions | B11: Tier 1 = Concorde Room (First Class, BA premier cardholders, Gold Guest List). Tier 2 = First Lounge (BA Gold). Tier 3 = Club Lounge (Club World/Club Europe, BA Silver).
A12: Tier 1 caveat | B12: There is no Concorde Room at Terminal 3 today. Tier 1 percentages model passengers who would qualify for that level of service, as a hypothetical/potential space to inform whether a Tier 1 lounge may be needed - not a confirmed development.
A13: Counting rule | B13: Mutually exclusive: every passenger is counted once, at the highest tier they qualify for. Percentages are of total boarded passengers on the flight and sum to total lounge-eligible share.
A14: Sheets | B14: 9 sheets - see the sheet-by-sheet guide below this table.
A15: Refresh cadence | B15: Re-run the category aggregation each schedule season (or against lounge access scans); only the rate cells change - groupings, formulas and sheet structure stay constant so results remain comparable.
A17: Sheet-by-sheet guide
A18: Sheet | B18: What it contains and how to use it
A19: Read Me | B19: This page: the purpose of the model, how it was built and validated, how to use it, grouping dimensions, tier definitions, counting rules, and this sheet guide. Start here.
A20: Dictionary | B20: 46 terms explained: abbreviations (STD, Pax, pp, LF), lounge tier names, model concepts (baseline / verified / recommended rate, variance) and every column of the Forage source dataset. Refer to it whenever a term on another sheet is unfamiliar.
A21: Data Preparation | B21: The audit trail - 11 steps showing exactly what was done to the Forage summer schedule to make it work with the lookup: parsing FLIGHT_TIME, mapping the dataset's 4 TIME_OF_DAY values to the model's 3 bands by clock hour, mapping ARRIVAL_REGION to route groups, converting seats to passengers at 85% load factor, calculating verified rates, and choosing the sample day.
A22: Recommended Lookup | B22: THE MAIN DELIVERABLE. A reusable 15-row table (5 route groups x 3 time bands) of verified Tier 1/2/3 eligibility percentages of boarded passengers, with total eligible %, the old baseline percentages for comparison, variance in pp, and the number of flights each rate rests on. Use these percentages for all future lounge demand estimates - multiply by expected passengers.
A23: Lookup Table | B23: The original assumption-based percentages from before validation against the schedule data, kept unchanged for audit and transparency. It still drives the Worked Example. Superseded by 'Recommended Lookup' for planning.
A24: Schedule Sample | B24: The lookup table tested on real data: every one of the 44 LHR departures on 18 June 2025, classified into a route group and time band, with recommended percentages pulled by live SUMIFS, eligible passengers modelled per tier, and compared with the dataset's actual TIER1/2/3 counts. The summary block underneath gives the verdict: modelled 1,713 vs actual 1,557 (+10%), versus the baseline model's 2,281 (+46%).
A25: Assumptions | B25: The judgement layer: base rates per route group with written rationale, the business-intensity time multipliers used in the baseline, and supporting notes covering the validation outcome, dataset coverage gaps (South America/Africa), the hypothetical Tier 1 caveat, load-factor treatment, what the model deliberately excludes, and conservatism.
A26: Worked Example | B26: An illustrative 14-flight day (hand-built, includes South America and evening long-haul) demonstrating the classify -> look up -> multiply workflow with live SUMIFS formulas against the baseline table. Companion to Schedule Sample, which does the same thing with real schedule data.
A27: Justification | B27: The written defence of the result in 7 sections: objective, why these groupings, how the rates were derived and recalibrated, the representative sample, defensibility of the numbers, how to reuse the table with future schedules, and limitations with next steps.

Sheet Dictionary
A1: Dictionary of Abbreviations & Terms
A2: Terminology used throughout this workbook and the defence slide
A4: Term / Abbreviation | B4: Full form | C4: Meaning in this model
A5: STD | B5: Scheduled Time of Departure | C5: The flight's scheduled departure time (local, 24h clock). Used to assign a flight to a time band: 05:00-09:59, 10:00-15:59 or 16:00-22:59.
A6: Pax | B6: Passengers | C6: Expected number of boarded passengers on a flight. The count the eligibility percentages are applied to.
A7: EL / Eligible | B7: Lounge eligibility | C7: A passenger who meets an access rule (premium cabin or BA status/card) and may therefore enter a lounge.
A8: Tier 1 | B8: Concorde Room tier | C8: Highest lounge tier: First Class customers, BA premier cardholders, BA Gold Guest List members.
A9: Tier 2 | B9: First Lounge tier | C9: Middle lounge tier: BA Gold members.
A10: Tier 3 | B10: Club Lounge tier | C10: Base lounge tier: Club World / Club Europe (business class) customers and BA Silver cardholders.
A11: BA | B11: British Airways | C11: The airline whose lounges at Heathrow Terminal 3 are being modelled.
A12: LHR | B12: London Heathrow | C12: Airport code for BA's main hub; lounges in this model sit in Terminal 3.
A13: T3 | B13: Terminal 3 | C13: Heathrow Terminal 3 - the terminal this lounge demand model applies to.
A14: GGL | B14: BA Gold Guest List | C14: BA's invitation-only top status tier; Concorde Room access alongside premier cardholders.
A15: Premier cardholder | B15: BA premier credit card holder | C15: Co-brand/premium cardholders granted lounge access under BA's card partnership rules (Tier 1).
... A50: TIER1/2/3_ELIGIBLE_PAX | B50: Dataset columns | C50: Actual passengers eligible for each lounge tier per flight - used as the benchmark to verify and recalibrate the model's percentages.

Sheet Data Preparation
A1: Data Preparation - From Source Schedule to Lookup Categories
A2: Every transformation applied to the Forage 'British Airways Summer Schedule Dataset' (10,000 rows) before the lookup percentages could be applied
A4: Step | B4: What was done | C4: Rule / reason
A5: 1. Load source dataset | B5: Read the file 'British Airways Summer Schedule Dataset - Forage Data Science Task 1.xlsx' (sheet: british_airways_schedule_summer): 10,000 rows x 17 columns - BA flights departing LHR, 1 Apr - 30 Oct 2025, 210 dates. | C5: Source for both the category rates and the per-flight benchmark (TIER1/2/3_ELIGIBLE_PAX).
A6: 2. Assign Time Band from clock time | B6: Parsed FLIGHT_TIME to an hour, then banded it into the model's 3 windows: 05:00-09:59 = Early morning, 10:00-15:59 = Midday, 16:00-22:59 = Evening. | C6: The lookup's time dimension is defined by scheduled departure hour, so the same rule works on any future schedule. (Dataset hours run 06:00-22:59.)
A7: 3. Map the dataset's 4 TIME_OF_DAY values | B7: Cross-checked the source label against the clock: Morning 06-11 -> Early morning for hours 06-09 and Midday for 10-11 | Lunchtime 12-13 -> Midday | Afternoon 14-17 -> Midday for 14-15 and Evening for 16-17 | Evening 18-22 -> Evening. | C7: The source has 4 day parts, the model uses 3 bands - mapping by hour resolves the overlaps (Morning/Afternoon straddle band edges). Band is always taken from FLIGHT_TIME; TIME_OF_DAY is only a consistency check.
A8: 4. Map ARRIVAL_REGION to Route Group | B8: Europe -> Europe & Domestic | North America -> North America | Asia -> Asia & Oceania | Middle East -> Middle East & Africa. | C8: The lookup's 5 route groups come from the model, not the file: region names differ and South America/Africa are absent from this schedule, so those cells stay as judgement rates (flagged on Recommended Lookup).
A9: 5. Confirm Route Type from HAUL | B9: SHORT -> Short-haul, LONG -> Long-haul; verified this agrees with route group (Europe = SHORT, all others = LONG). | C9: Keeps the 'Route Type' column of the lookup populated. AIRCRAFT_TYPE (A320/A350/A380/B777/B787) was deliberately NOT used, so the table stays valid when the fleet plan changes.
A10: 6. Convert seats to passengers | B10: Pax = (FIRST_CLASS_SEATS + BUSINESS_CLASS_SEATS + ECONOMY_SEATS) x 85% load factor, rounded per flight. | C10: The dataset lists seats, not passengers, but the lookup percentages are per boarded passenger; 85% is the stated load-factor assumption for verification.
A11: 7. Calculate verified rates per cell | B11: For each of the 15 Route Group x Time Band cells: verified % = sum of TIER1/2/3_ELIGIBLE_PAX / (seats x 85%) x 100, rounded to 0.1pp (each cell rests on 153-2,491 flights). | C11: These are the 'verified' columns on Recommended Lookup; South America uses judgement rates re-based on the verified long-haul pattern because it has no flights in the source.
A12: 8. Select the representative sample | B12: Chose 18 June 2025: a full operating day covering all 4 source regions and all 3 time bands - 44 flights, 10,471 seats, 8,901 passengers (from 194 candidate dates that cover all 4 regions). | C12: Task guidance: analyse a representative slice, not all 10,000 rows - a complete day tests every grouping dimension at once.
A13: 9. Apply the lookup to the sample | B13: On the Schedule Sample sheet each flight is classified (Route Group + Time Band), Tier % is pulled with live SUMIFS against Recommended Lookup, multiplied by Pax and rounded; totals are compared with the dataset's own TIER1/2/3_ELIGIBLE_PAX (variance column). | C13: Demonstrates the reusable workflow: classify -> look up -> multiply -> compare. Recalibrated result = 1,713 eligible vs 1,557 actual (+10%); baseline assumption model = 2,281 (+46%).
A14: 10. Recalibrate and retain the baseline | B14: Verified rates replaced the assumption-based rates on Recommended Lookup; the original judgement table is kept unchanged on the 'Lookup Table' sheet. | C14: Validation showed the baseline ran +46% vs actual (over-weighting long-haul, under-weighting Europe); keeping both tables makes the correction auditable.
A15: 11. Refresh procedure | B15: Re-run steps 1-7 whenever a new schedule extract arrives (or against actual lounge access scans), overwriting only the rate columns. | C15: Columns, groupings, formulas and sheet structure stay fixed, so results remain comparable between seasons and to lounge-access data.

Sheet Recommended Lookup
A1: Recommended Lookup Table - Lounge Eligibility by Flight Grouping
A2: Data-calibrated on 10,000 BA summer-2025 flights | % of boarded passengers (85% load factor) | tiers mutually exclusive
A4: Route Group | B4: Route Type | C4: Time Band | D4: Tier 1 - Concorde Room % | E4: Tier 2 - First Lounge % | F4: Tier 3 - Club Lounge % | G4: Total Eligible % | H4: Baseline Tier 1 % | I4: Baseline Tier 2 % | J4: Baseline Tier 3 % | K4: Total variance vs baseline | L4: Flights in dataset | M4: Basis
A5: Europe & Domestic | B5: Short-haul | C5: Early morning | D5: 0.004 | E5: 0.051 | F5: 0.196 | G5: 0.251 | H5: 0.003 | I5: 0.014 | J5: 0.195 | K5: 3.9 | L5: 1371 | M5: Verified: 1,371 flights, Apr-Oct 2025, LHR
A6: Europe & Domestic | B6: Short-haul | C6: Midday | D6: 0.004 | E6: 0.052 | F6: 0.199 | G6: 0.255 | H6: 0.002 | I6: 0.008 | J6: 0.113 | K6: 13.2 | L6: 2113 | M6: Verified: 2,113 flights, Apr-Oct 2025, LHR
A7: Europe & Domestic | B7: Short-haul | C7: Evening | D7: 0.004 | E7: 0.052 | F7: 0.199 | G7: 0.255 | H7: 0.002 | I7: 0.012 | J7: 0.165 | K7: 7.6 | L7: 2491 | M7: Verified: 2,491 flights, Apr-Oct 2025, LHR
A8: North America | B8: Long-haul | C8: Early morning | D8: 0.002 | E8: 0.033 | F8: 0.127 | G8: 0.162 | H8: 0.025 | I8: 0.025 | J8: 0.31 | K8: -19.8 | L8: 648 | M8: Verified: 648 flights, Apr-Oct 2025, LHR
A9: North America | B9: Long-haul | C9: Midday | D9: 0.002 | E9: 0.032 | F9: 0.123 | G9: 0.157 | H9: 0.02 | I9: 0.02 | J9: 0.243 | K9: -12.6 | L9: 918 | M9: Verified: 918 flights, Apr-Oct 2025, LHR
A10: North America | B10: Long-haul | C10: Evening | D10: 0.002 | E10: 0.032 | F10: 0.123 | G10: 0.157 | H10: 0.024 | I10: 0.024 | J10: 0.297 | K10: -18.8 | L10: 1092 | M10: Verified: 1,092 flights, Apr-Oct 2025, LHR
A11: Asia & Oceania | B11: Long-haul | C11: Early morning | D11: 0.003 | E11: 0.032 | F11: 0.124 | G11: 0.159 | H11: 0.031 | I11: 0.028 | J11: 0.333 | K11: -23.3 | L11: 153 | M11: Verified: 153 flights, Apr-Oct 2025, LHR
A12: Asia & Oceania | B12: Long-haul | C12: Midday | D12: 0.002 | E12: 0.032 | F12: 0.121 | G12: 0.155 | H12: 0.024 | I12: 0.022 | J12: 0.261 | K12: -15.2 | L12: 254 | M12: Verified: 254 flights, Apr-Oct 2025, LHR
A13: Asia & Oceania | B13: Long-haul | C13: Evening | D13: 0.002 | E13: 0.032 | F13: 0.122 | G13: 0.156 | H13: 0.03 | I13: 0.026 | J13: 0.319 | K13: -21.9 | L13: 272 | M13: Verified: 272 flights, Apr-Oct 2025, LHR
A14: Middle East & Africa | B14: Long-haul | C14: Early morning | D14: 0.002 | E14: 0.033 | F14: 0.125 | G14: 0.16 | H14: 0.02 | I14: 0.021 | J14: 0.259 | K14: -14 | L14: 189 | M14: Verified: 189 flights, Apr-Oct 2025, LHR
A15: Middle East & Africa | B15: Long-haul | C15: Midday | D15: 0.002 | E15: 0.032 | F15: 0.123 | G15: 0.157 | H15: 0.015 | I15: 0.016 | J15: 0.203 | K15: -7.7 | L15: 210 | M15: Verified: 210 flights, Apr-Oct 2025, LHR
A16: Middle East & Africa | B16: Long-haul | C16: Evening | D16: 0.002 | E16: 0.03 | F16: 0.117 | G16: 0.149 | H16: 0.019 | I16: 0.02 | J16: 0.248 | K16: -13.8 | L16: 289 | M16: Verified: 289 flights, Apr-Oct 2025, LHR
... A19: South America | B19: Long-haul | C19: Evening | D19: 0.002 | E19: 0.03 | F19: 0.116 | G19: 0.148 | H19: 0.015 | I19: 0.017 | J19: 0.226 | K19: -11 | L19: 0 | M19: Judgement re-based on verified long-haul rates (region absent from dataset)

Sheet Lookup Table
A1: Baseline Lookup Table (assumption model) - kept for transparency
A2: Original judgement-based rates before schedule validation; superseded by 'Recommended Lookup' for planning use
A4: Route Group | B4: Route Type | C4: Time Band | D4: Tier 1 - Concorde Room % | E4: Tier 2 - First Lounge % | F4: Tier 3 - Club Lounge % | G4: Total Lounge Eligible % | H4: Time Band Definition
A5: Europe & Domestic | B5: Short-haul | C5: Early morning | D5: 0.003 | E5: 0.014 | F5: 0.195 | G5: 0.212 | H5: 05:00-09:59 STD
A6: Europe & Domestic | B6: Short-haul | C6: Midday | D6: 0.002 | E6: 0.008 | F6: 0.113 | G6: 0.123 | H6: 10:00-15:59 STD
A7: Europe & Domestic | B7: Short-haul | C7: Evening | D7: 0.002 | E7: 0.012 | F7: 0.165 | G7: 0.179 | H7: 16:00-22:59 STD
A8: North America | B8: Long-haul | C8: Early morning | D8: 0.025 | E8: 0.025 | F8: 0.31 | G8: 0.36 | H8: 05:00-09:59 STD
A9: North America | B9: Long-haul | C9: Midday | D9: 0.02 | E9: 0.02 | F9: 0.243 | G9: 0.283 | H9: 10:00-15:59 STD
A10: North America | B10: Long-haul | C10: Evening | D10: 0.024 | E10: 0.024 | F10: 0.297 | G10: 0.345 | H10: 16:00-22:59 STD
A11: Asia & Oceania | B11: Long-haul | C11: Early morning | D11: 0.031 | E11: 0.028 | F11: 0.333 | G11: 0.392 | H11: 05:00-09:59 STD
A12: Asia & Oceania | B12: Long-haul | C12: Midday | D12: 0.024 | E12: 0.022 | F12: 0.261 | G12: 0.307 | H12: 10:00-15:59 STD
A13: Asia & Oceania | B13: Long-haul | C13: Evening | D13: 0.03 | E13: 0.026 | F13: 0.319 | G13: 0.375 | H13: 16:00-22:59 STD
A14: Middle East & Africa | B14: Long-haul | C14: Early morning | D14: 0.02 | E14: 0.021 | F14: 0.259 | G14: 0.3 | H14: 05:00-09:59 STD
A15: Middle East & Africa | B15: Long-haul | C15: Midday | D15: 0.015 | E15: 0.016 | F15: 0.203 | G15: 0.234 | H15: 10:00-15:59 STD
A16: Middle East & Africa | B16: Long-haul | C16: Evening | D16: 0.019 | E16: 0.02 | F16: 0.248 | G16: 0.287 | H16: 16:00-22:59 STD
... A19: South America | B19: Long-haul | C19: Evening | D19: 0.015 | E19: 0.017 | F19: 0.226 | G19: 0.258 | H19: 16:00-22:59 STD

Sheet Schedule Sample
A1: Schedule Sample - Representative Day Assigned to Categories
A2: 18 Jun 2025: every LHR departure classified by Route Group + Time Band; recommended % applied live via SUMIFS and compared with the dataset's actual eligible counts
A4: Flight No. | B4: Departure Time | C4: Destination | D4: Region | E4: Route Type | F4: Category: Route Group | G4: Category: Time Band | H4: Seats | I4: Pax (85%) | J4: Tier 1 % | K4: Tier 2 % | L4: Tier 3 % | M4: Tier 1 pax | N4: Tier 2 pax | O4: Tier 3 pax | P4: Total modelled | Q4: Actual Tier 1 | R4: Actual Tier 2 | S4: Actual Tier 3 | T4: Actual total | U4: Variance
A5: BA4609 | B5: 06:09 | C5: DXB - UAE | D5: Middle East | E5: Long-haul | F5: Middle East & Africa | G5: Early morning | H5: 256 | I5: 218 | J5: =SUMIFS('Recommended Lookup'!$D$5:$D$19,'Recommended Lookup'!$A$5:$A$19,$F5,'Recommended Lookup'!$C$5:$C$19,$G5) | K5: =SUMIFS('Recommended Lookup'!$E$5:$E$19,'Recommended Lookup'!$A$5:$A$19,$F5,'Recommended Lookup'!$C$5:$C$19,$G5) | L5: =SUMIFS('Recommended Lookup'!$F$5:$F$19,'Recommended Lookup'!$A$5:$A$19,$F5,'Recommended Lookup'!$C$5:$C$19,$G5) | M5: =ROUND($I5*J5,0) | N5: =ROUND($I5*K5,0) | O5: =ROUND($I5*L5,0) | P5: =SUM(M5:O5) | Q5: 1 | R5: 1 | S5: 11 | T5: =SUM(Q5:S5) | U5: =P5-T5
A6: BA9934 | B6: 06:35 | C6: AMS - Netherlands | D6: Europe | E6: Short-haul | F6: Europe & Domestic | G6: Early morning | H6: 180 | I6: 153 | J6: =SUMIFS('Recommended Lookup'!$D$5:$D$19,'Recommended Lookup'!$A$5:$A$19,$F6,'Recommended Lookup'!$C$5:$C$19,$G6) | K6: =SUMIFS('Recommended Lookup'!$E$5:$E$19,'Recommended Lookup'!$A$5:$A$19,$F6,'Recommended Lookup'!$C$5:$C$19,$G6) | L6: =SUMIFS('Recommended Lookup'!$F$5:$F$19,'Recommended Lookup'!$A$5:$A$19,$F6,'Recommended Lookup'!$C$5:$C$19,$G6) | M6: =ROUND($I6*J6,0) | N6: =ROUND($I6*K6,0) | O6: =ROUND($I6*L6,0) | P6: =SUM(M6:O6) | Q6: 1 | R6: 13 | S6: 47 | T6: =SUM(Q6:S6) | U6: =P6-T6
A7: BA5810 | B7: 07:31 | C7: LAX - USA | D7: North America | E7: Long-haul | F7: North America | G7: Early morning | H7: 256 | I7: 218 | J7: =SUMIFS('Recommended Lookup'!$D$5:$D$19,'Recommended Lookup'!$A$5:$A$19,$F7,'Recommended Lookup'!$C$5:$C$19,$G7) | K7: =SUMIFS('Recommended Lookup'!$E$5:$E$19,'Recommended Lookup'!$A$5:$A$19,$F7,'Recommended Lookup'!$C$5:$C$19,$G7) | L7: =SUMIFS('Recommended Lookup'!$F$5:$F$19,'Recommended Lookup'!$A$5:$A$19,$F7,'Recommended Lookup'!$C$5:$C$19,$G7) | M7: =ROUND($I7*J7,0) | N7: =ROUND($I7*K7,0) | O7: =ROUND($I7*L7,0) | P7: =SUM(M7:O7) | Q7: 0 | R7: 0 | S7: 7 | T7: =SUM(Q7:S7) | U7: =P7-T7
A8: BA2551 | B8: 08:22 | C8: VIE - Austria | D8: Europe | E8: Short-haul | F8: Europe & Domestic | G8: Early morning | H8: 180 | I8: 153 | J8: =SUMIFS('Recommended Lookup'!$D$5:$D$19,'Recommended Lookup'!$A$5:$A$19,$F8,'Recommended Lookup'!$C$5:$C$19,$G8) | K8: =SUMIFS('Recommended Lookup'!$E$5:$E$19,'Recommended Lookup'!$A$5:$A$19,$F8,'Recommended Lookup'!$C$5:$C$19,$G8) | L8: =SUMIFS('Recommended Lookup'!$F$5:$F$19,'Recommended Lookup'!$A$5:$A$19,$F8,'Recommended Lookup'!$C$5:$C$19,$G8) | M8: =ROUND($I8*J8,0) | N8: =ROUND($I8*K8,0) | O8: =ROUND($I8*L8,0) | P8: =SUM(M8:O8) | Q8: 0 | R8: 7 | S8: 27 | T8: =SUM(Q8:S8) | U8: =P8-T8
A9: BA1921 | B9: 09:08 | C9: MAD - Spain | D9: Europe | E9: Short-haul | F9: Europe & Domestic | G9: Early morning | H9: 180 | I9: 153 | J9: =SUMIFS('Recommended Lookup'!$D$5:$D$19,'Recommended Lookup'!$A$5:$A$19,$F9,'Recommended Lookup'!$C$5:$C$19,$G9) | K9: =SUMIFS('Recommended Lookup'!$E$5:$E$19,'Recommended Lookup'!$A$5:$A$19,$F9,'Recommended Lookup'!$C$5:$C$19,$G9) | L9: =SUMIFS('Recommended Lookup'!$F$5:$F$19,'Recommended Lookup'!$A$5:$A$19,$F9,'Recommended Lookup'!$C$5:$C$19,$G9) | M9: =ROUND($I9*J9,0) | N9: =ROUND($I9*K9,0) | O9: =ROUND($I9*L9,0) | P9: =SUM(M9:O9) | Q9: 1 | R9: 6 | S9: 26 | T9: =SUM(Q9:S9) | U9: =P9-T9
A10: BA7910 | B10: 09:21 | C10: HND - Japan | D10: Asia | E10: Long-haul | F10: Asia & Oceania | G10: Early morning | H10: 332 | I10: 282 | J10: =SUMIFS('Recommended Lookup'!$D$5:$D$19,'Recommended Lookup'!$A$5:$A$19,$F10,'Recommended Lookup'!$C$5:$C$19,$G10) | K10: =SUMIFS('Recommended Lookup'!$E$5:$E$19,'Recommended Lookup'!$A$5:$A$19,$F10,'Recommended Lookup'!$C$5:$C$19,$G10) | L10: =SUMIFS('Recommended Lookup'!$F$5:$F$19,'Recommended Lookup'!$A$5:$A$19,$F10,'Recommended Lookup'!$C$5:$C$19,$G10) | M10: =ROUND($I10*J10,0) | N10: =ROUND($I10*K10,0) | O10: =ROUND($I10*L10,0) | P10: =SUM(M10:O10) | Q10: 0 | R10: 10 | S10: 38 | T10: =SUM(Q10:S10) | U10: =P10-T10
A11: BA3345 | B11: 09:28 | C11: DXB - UAE | D11: Middle East | E11: Long-haul | F11: Middle East & Africa | G11: Early morning | H11: 235 | I11: 200 | J11: =SUMIFS('Recommended Lookup'!$D$5:$D$19,'Recommended Lookup'!$A$5:$A$19,$F11,'Recommended Lookup'!$C$5:$C$19,$G11) | K11: =SUMIFS('Recommended Lookup'!$E$5:$E$19,'Recommended Lookup'!$A$5:$A$19,$F11,'Recommended Lookup'!$C$5:$C$19,$G11) | L11: =SUMIFS('Recommended Lookup'!$F$5:$F$19,'Recommended Lookup'!$A$5:$A$19,$F11,'Recommended Lookup'!$C$5:$C$19,$G11) | M11: =ROUND($I11*J11,0) | N11: =ROUND($I11*K11,0) | O11: =ROUND($I11*L11,0) | P11: =SUM(M11:O11) | Q11: 0 | R11: 12 | S11: 42 | T11: =SUM(Q11:S11) | U11: =P11-T11
A12: BA4690 | B12: 09:57 | C12: DXB - UAE | D12: Middle East | E12: Long-haul | F12: Middle East & Africa | G12: Early morning | H12: 235 | I12: 200 | J12: =SUMIFS('Recommended Lookup'!$D$5:$D$19,'Recommended Lookup'!$A$5:$A$19,$F12,'Recommended Lookup'!$C$5:$C$19,$G12) | K12: =SUMIFS('Recommended Lookup'!$E$5:$E$19,'Recommended Lookup'!$A$5:$A$19,$F12,'Recommended Lookup'!$C$5:$C$19,$G12) | L12: =SUMIFS('Recommended Lookup'!$F$5:$F$19,'Recommended Lookup'!$A$5:$A$19,$F12,'Recommended Lookup'!$C$5:$C$19,$G12) | M12: =ROUND($I12*J12,0) | N12: =ROUND($I12*K12,0) | O12: =ROUND($I12*L12,0) | P12: =SUM(M12:O12) | Q12: 0 | R12: 0 | S12: 4 | T12: =SUM(Q12:S12) | U12: =P12-T12
A13: BA6427 | B13: 10:11 | C13: DXB - UAE | D13: Middle East | E13: Long-haul | F13: Middle East & Africa | G13: Midday | H13: 469 | I13: 399 | J13: =SUMIFS('Recommended Lookup'!$D$5:$D$19,'Recommended Lookup'!$A$5:$A$19,$F13,'Recommended Lookup'!$C$5:$C$19,$G13) | K13: =SUMIFS('Recommended Lookup'!$E$5:$E$19,'Recommended Lookup'!$A$5:$A$19,$F13,'Recommended Lookup'!$C$5:$C$19,$G13) | L13: =SUMIFS('Recommended Lookup'!$F$5:$F$19,'Recommended Lookup'!$A$5:$A$19,$F13,'Recommended Lookup'!$C$5:$C$19,$G13) | M13: =ROUND($I13*J13,0) | N13: =ROUND($I13*K13,0) | O13: =ROUND($I13*L13,0) | P13: =SUM(M13:O13) | Q13: 0 | R13: 8 | S13: 31 | T13: =SUM(Q13:S13) | U13: =P13-T13
A14: BA6938 | B14: 10:21 | C14: FRA - Germany | D14: Europe | E14: Short-haul | F14: Europe & Domestic | G14: Midday | H14: 180 | I14: 153 | J14: =SUMIFS('Recommended Lookup'!$D$5:$D$19,'Recommended Lookup'!$A$5:$A$19,$F14,'Recommended Lookup'!$C$5:$C$19,$G14) | K14: =SUMIFS('Recommended Lookup'!$E$5:$E$19,'Recommended Lookup'!$A$5:$A$19,$F14,'Recommended Lookup'!$C$5:$C$19,$G14) | L14: =SUMIFS('Recommended Lookup'!$F$5:$F$19,'Recommended Lookup'!$A$5:$A$19,$F14,'Recommended Lookup'!$C$5:$C$19,$G14) | M14: =ROUND($I14*J14,0) | N14: =ROUND($I14*K14,0) | O14: =ROUND($I14*L14,0) | P14: =SUM(M14:O14) | Q14: 0 | R14: 16 | S14: 54 | T14: =SUM(Q14:S14) | U14: =P14-T14
A15: BA9611 | B15: 10:24 | C15: VIE - Austria | D15: Europe | E15: Short-haul | F15: Europe & Domestic | G15: Midday | H15: 180 | I15: 153 | J15: =SUMIFS('Recommended Lookup'!$D$5:$D$19,'Recommended Lookup'!$A$5:$A$19,$F15,'Recommended Lookup'!$C$5:$C$19,$G15) | K15: =SUMIFS('Recommended Lookup'!$E$5:$E$19,'Recommended Lookup'!$A$5:$A$19,$F15,'Recommended Lookup'!$C$5:$C$19,$G15) | L15: =SUMIFS('Recommended Lookup'!$F$5:$F$19,'Recommended Lookup'!$A$5:$A$19,$F15,'Recommended Lookup'!$C$5:$C$19,$G15) | M15: =ROUND($I15*J15,0) | N15: =ROUND($I15*K15,0) | O15: =ROUND($I15*L15,0) | P15: =SUM(M15:O15) | Q15: 0 | R15: 0 | S15: 7 | T15: =SUM(Q15:S15) | U15: =P15-T15
A16: BA4218 | B16: 10:42 | C16: LAX - USA | D16: North America | E16: Long-haul | F16: North America | G16: Midday | H16: 256 | I16: 218 | J16: =SUMIFS('Recommended Lookup'!$D$5:$D$19,'Recommended Lookup'!$A$5:$A$19,$F16,'Recommended Lookup'!$C$5:$C$19,$G16) | K16: =SUMIFS('Recommended Lookup'!$E$5:$E$19,'Recommended Lookup'!$A$5:$A$19,$F16,'Recommended Lookup'!$C$5:$C$19,$G16) | L16: =SUMIFS('Recommended Lookup'!$F$5:$F$19,'Recommended Lookup'!$A$5:$A$19,$F16,'Recommended Lookup'!$C$5:$C$19,$G16) | M16: =ROUND($I16*J16,0) | N16: =ROUND($I16*K16,0) | O16: =ROUND($I16*L16,0) | P16: =SUM(M16:O16) | Q16: 0 | R16: 5 | S16: 23 | T16: =SUM(Q16:S16) | U16: =P16-T16
... A48: BA2137 | B48: 22:43 | C48: VIE - Austria | D48: Europe | E48: Short-haul | F48: Europe & Domestic | G48: Evening | H48: 180 | I48: 153 | J48: =SUMIFS('Recommended Lookup'!$D$5:$D$19,'Recommended Lookup'!$A$5:$A$19,$F48,'Recommended Lookup'!$C$5:$C$19,$G48) | K48: =SUMIFS('Recommended Lookup'!$E$5:$E$19,'Recommended Lookup'!$A$5:$A$19,$F48,'Recommended Lookup'!$C$5:$C$19,$G48) | L48: =SUMIFS('Recommended Lookup'!$F$5:$F$19,'Recommended Lookup'!$A$5:$A$19,$F48,'Recommended Lookup'!$C$5:$C$19,$G48) | M48: =ROUND($I48*J48,0) | N48: =ROUND($I48*K48,0) | O48: =ROUND($I48*L48,0) | P48: =SUM(M48:O48) | Q48: 0 | R48: 10 | S48: 36 | T48: =SUM(Q48:S48) | U48: =P48-T48
A49: TOTAL | H49: =SUM(H5:H48) | I49: =SUM(I5:I48) | M49: =SUM(M5:M48) | N49: =SUM(N5:N48) | O49: =SUM(O5:O48) | P49: =SUM(P5:P48) | Q49: =SUM(Q5:Q48) | R49: =SUM(R5:R48) | S49: =SUM(S5:S48) | T49: =SUM(T5:T48) | U49: =SUM(U5:U48)
A51: Sample day comparison
A52: Recommended lookup (data-calibrated) - modelled eligible | F52: =P49 | G52: +10.0% vs schedule actual
A53: Baseline assumption model - modelled eligible | F53: 2281 | G53: +46.5% vs schedule actual
A54: Schedule dataset actual eligible (TIER1+2+3) | F54: =T49 | G54: benchmark
A55: Of which hypothetical Tier 1 (future Tier 1 / Concorde space at T3) | F55: =Q49 | G55: no Concorde Room at T3 today
A58: Evaluation by category x time band - where the model should be judged (modelled vs actual)
A59: Category | C59: Time band | D59: Tier 1 - Concorde Room (hypothetical) | G59: Tier 2 - First Lounge | J59: Tier 3 - Club Lounge | M59: Total eligible | P59: Var%
D60: Modelled | E60: Actual | F60: Var | G60: Modelled | H60: Actual | I60: Var | J60: Modelled | K60: Actual | L60: Var | M60: Modelled | N60: Actual | O60: Var
A61: Middle East & Africa | C61: Early morning | D61: =SUMIFS(M$5:M$48,$F$5:$F$48,$A61,$G$5:$G$48,$C61) | E61: =SUMIFS(Q$5:Q$48,$F$5:$F$48,$A61,$G$5:$G$48,$C61) | F61: =D61-E61 | G61: =SUMIFS(N$5:N$48,$F$5:$F$48,$A61,$G$5:$G$48,$C61) | H61: =SUMIFS(R$5:R$48,$F$5:$F$48,$A61,$G$5:$G$48,$C61) | I61: =G61-H61 | J61: =SUMIFS(O$5:O$48,$F$5:$F$48,$A61,$G$5:$G$48,$C61) | K61: =SUMIFS(S$5:S$48,$F$5:$F$48,$A61,$G$5:$G$48,$C61) | L61: =J61-K61 | M61: =SUM(D61,G61,J61) | N61: =SUM(E61,H61,K61) | O61: =M61-N61 | P61: =IF(N61=0,"",M61/N61-1)
A62: Europe & Domestic | C62: Early morning | D62: =SUMIFS(M$5:M$48,$F$5:$F$48,$A62,$G$5:$G$48,$C62) | E62: =SUMIFS(Q$5:Q$48,$F$5:$F$48,$A62,$G$5:$G$48,$C62) | F62: =D62-E62 | G62: =SUMIFS(N$5:N$48,$F$5:$F$48,$A62,$G$5:$G$48,$C62) | H62: =SUMIFS(R$5:R$48,$F$5:$F$48,$A62,$G$5:$G$48,$C62) | I62: =G62-H62 | J62: =SUMIFS(O$5:O$48,$F$5:$F$48,$A62,$G$5:$G$48,$C62) | K62: =SUMIFS(S$5:S$48,$F$5:$F$48,$A62,$G$5:$G$48,$C62) | L62: =J62-K62 | M62: =SUM(D62,G62,J62) | N62: =SUM(E62,H62,K62) | O62: =M62-N62 | P62: =IF(N62=0,"",M62/N62-1)
A63: North America | C63: Early morning | D63: =SUMIFS(M$5:M$48,$F$5:$F$48,$A63,$G$5:$G$48,$C63) | E63: =SUMIFS(Q$5:Q$48,$F$5:$F$48,$A63,$G$5:$G$48,$C63) | F63: =D63-E63 | G63: =SUMIFS(N$5:N$48,$F$5:$F$48,$A63,$G$5:$G$48,$C63) | H63: =SUMIFS(R$5:R$48,$F$5:$F$48,$A63,$G$5:$G$48,$C63) | I63: =G63-H63 | J63: =SUMIFS(O$5:O$48,$F$5:$F$48,$A63,$G$5:$G$48,$C63) | K63: =SUMIFS(S$5:S$48,$F$5:$F$48,$A63,$G$5:$G$48,$C63) | L63: =J63-K63 | M63: =SUM(D63,G63,J63) | N63: =SUM(E63,H63,K63) | O63: =M63-N63 | P63: =IF(N63=0,"",M63/N63-1)
A64: Asia & Oceania | C64: Early morning | D64: =SUMIFS(M$5:M$48,$F$5:$F$48,$A64,$G$5:$G$48,$C64) | E64: =SUMIFS(Q$5:Q$48,$F$5:$F$48,$A64,$G$5:$G$48,$C64) | F64: =D64-E64 | G64: =SUMIFS(N$5:N$48,$F$5:$F$48,$A64,$G$5:$G$48,$C64) | H64: =SUMIFS(R$5:R$48,$F$5:$F$48,$A64,$G$5:$G$48,$C64) | I64: =G64-H64 | J64: =SUMIFS(O$5:O$48,$F$5:$F$48,$A64,$G$5:$G$48,$C64) | K64: =SUMIFS(S$5:S$48,$F$5:$F$48,$A64,$G$5:$G$48,$C64) | L64: =J64-K64 | M64: =SUM(D64,G64,J64) | N64: =SUM(E64,H64,K64) | O64: =M64-N64 | P64: =IF(N64=0,"",M64/N64-1)
A65: Middle East & Africa | C65: Midday | D65: =SUMIFS(M$5:M$48,$F$5:$F$48,$A65,$G$5:$G$48,$C65) | E65: =SUMIFS(Q$5:Q$48,$F$5:$F$48,$A65,$G$5:$G$48,$C65) | F65: =D65-E65 | G65: =SUMIFS(N$5:N$48,$F$5:$F$48,$A65,$G$5:$G$48,$C65) | H65: =SUMIFS(R$5:R$48,$F$5:$F$48,$A65,$G$5:$G$48,$C65) | I65: =G65-H65 | J65: =SUMIFS(O$5:O$48,$F$5:$F$48,$A65,$G$5:$G$48,$C65) | K65: =SUMIFS(S$5:S$48,$F$5:$F$48,$A65,$G$5:$G$48,$C65) | L65: =J65-K65 | M65: =SUM(D65,G65,J65) | N65: =SUM(E65,H65,K65) | O65: =M65-N65 | P65: =IF(N65=0,"",M65/N65-1)
A66: Europe & Domestic | C66: Midday | D66: =SUMIFS(M$5:M$48,$F$5:$F$48,$A66,$G$5:$G$48,$C66) | E66: =SUMIFS(Q$5:Q$48,$F$5:$F$48,$A66,$G$5:$G$48,$C66) | F66: =D66-E66 | G66: =SUMIFS(N$5:N$48,$F$5:$F$48,$A66,$G$5:$G$48,$C66) | H66: =SUMIFS(R$5:R$48,$F$5:$F$48,$A66,$G$5:$G$48,$C66) | I66: =G66-H66 | J66: =SUMIFS(O$5:O$48,$F$5:$F$48,$A66,$G$5:$G$48,$C66) | K66: =SUMIFS(S$5:S$48,$F$5:$F$48,$A66,$G$5:$G$48,$C66) | L66: =J66-K66 | M66: =SUM(D66,G66,J66) | N66: =SUM(E66,H66,K66) | O66: =M66-N66 | P66: =IF(N66=0,"",M66/N66-1)
A67: North America | C67: Midday | D67: =SUMIFS(M$5:M$48,$F$5:$F$48,$A67,$G$5:$G$48,$C67) | E67: =SUMIFS(Q$5:Q$48,$F$5:$F$48,$A67,$G$5:$G$48,$C67) | F67: =D67-E67 | G67: =SUMIFS(N$5:N$48,$F$5:$F$48,$A67,$G$5:$G$48,$C67) | H67: =SUMIFS(R$5:R$48,$F$5:$F$48,$A67,$G$5:$G$48,$C67) | I67: =G67-H67 | J67: =SUMIFS(O$5:O$48,$F$5:$F$48,$A67,$G$5:$G$48,$C67) | K67: =SUMIFS(S$5:S$48,$F$5:$F$48,$A67,$G$5:$G$48,$C67) | L67: =J67-K67 | M67: =SUM(D67,G67,J67) | N67: =SUM(E67,H67,K67) | O67: =M67-N67 | P67: =IF(N67=0,"",M67/N67-1)
A68: Asia & Oceania | C68: Midday | D68: =SUMIFS(M$5:M$48,$F$5:$F$48,$A68,$G$5:$G$48,$C68) | E68: =SUMIFS(Q$5:Q$48,$F$5:$F$48,$A68,$G$5:$G$48,$C68) | F68: =D68-E68 | G68: =SUMIFS(N$5:N$48,$F$5:$F$48,$A68,$G$5:$G$48,$C68) | H68: =SUMIFS(R$5:R$48,$F$5:$F$48,$A68,$G$5:$G$48,$C68) | I68: =G68-H68 | J68: =SUMIFS(O$5:O$48,$F$5:$F$48,$A68,$G$5:$G$48,$C68) | K68: =SUMIFS(S$5:S$48,$F$5:$F$48,$A68,$G$5:$G$48,$C68) | L68: =J68-K68 | M68: =SUM(D68,G68,J68) | N68: =SUM(E68,H68,K68) | O68: =M68-N68 | P68: =IF(N68=0,"",M68/N68-1)
A69: Europe & Domestic | C69: Evening | D69: =SUMIFS(M$5:M$48,$F$5:$F$48,$A69,$G$5:$G$48,$C69) | E69: =SUMIFS(Q$5:Q$48,$F$5:$F$48,$A69,$G$5:$G$48,$C69) | F69: =D69-E69 | G69: =SUMIFS(N$5:N$48,$F$5:$F$48,$A69,$G$5:$G$48,$C69) | H69: =SUMIFS(R$5:R$48,$F$5:$F$48,$A69,$G$5:$G$48,$C69) | I69: =G69-H69 | J69: =SUMIFS(O$5:O$48,$F$5:$F$48,$A69,$G$5:$G$48,$C69) | K69: =SUMIFS(S$5:S$48,$F$5:$F$48,$A69,$G$5:$G$48,$C69) | L69: =J69-K69 | M69: =SUM(D69,G69,J69) | N69: =SUM(E69,H69,K69) | O69: =M69-N69 | P69: =IF(N69=0,"",M69/N69-1)
A70: North America | C70: Evening | D70: =SUMIFS(M$5:M$48,$F$5:$F$48,$A70,$G$5:$G$48,$C70) | E70: =SUMIFS(Q$5:Q$48,$F$5:$F$48,$A70,$G$5:$G$48,$C70) | F70: =D70-E70 | G70: =SUMIFS(N$5:N$48,$F$5:$F$48,$A70,$G$5:$G$48,$C70) | H70: =SUMIFS(R$5:R$48,$F$5:$F$48,$A70,$G$5:$G$48,$C70) | I70: =G70-H70 | J70: =SUMIFS(O$5:O$48,$F$5:$F$48,$A70,$G$5:$G$48,$C70) | K70: =SUMIFS(S$5:S$48,$F$5:$F$48,$A70,$G$5:$G$48,$C70) | L70: =J70-K70 | M70: =SUM(D70,G70,J70) | N70: =SUM(E70,H70,K70) | O70: =M70-N70 | P70: =IF(N70=0,"",M70/N70-1)
A71: Middle East & Africa | C71: Evening | D71: =SUMIFS(M$5:M$48,$F$5:$F$48,$A71,$G$5:$G$48,$C71) | E71: =SUMIFS(Q$5:Q$48,$F$5:$F$48,$A71,$G$5:$G$48,$C71) | F71: =D71-E71 | G71: =SUMIFS(N$5:N$48,$F$5:$F$48,$A71,$G$5:$G$48,$C71) | H71: =SUMIFS(R$5:R$48,$F$5:$F$48,$A71,$G$5:$G$48,$C71) | I71: =G71-H71 | J71: =SUMIFS(O$5:O$48,$F$5:$F$48,$A71,$G$5:$G$48,$C71) | K71: =SUMIFS(S$5:S$48,$F$5:$F$48,$A71,$G$5:$G$48,$C71) | L71: =J71-K71 | M71: =SUM(D71,G71,J71) | N71: =SUM(E71,H71,K71) | O71: =M71-N71 | P71: =IF(N71=0,"",M71/N71-1)
A72: Asia & Oceania | C72: Evening | D72: =SUMIFS(M$5:M$48,$F$5:$F$48,$A72,$G$5:$G$48,$C72) | E72: =SUMIFS(Q$5:Q$48,$F$5:$F$48,$A72,$G$5:$G$48,$C72) | F72: =D72-E72 | G72: =SUMIFS(N$5:N$48,$F$5:$F$48,$A72,$G$5:$G$48,$C72) | H72: =SUMIFS(R$5:R$48,$F$5:$F$48,$A72,$G$5:$G$48,$C72) | I72: =G72-H72 | J72: =SUMIFS(O$5:O$48,$F$5:$F$48,$A72,$G$5:$G$48,$C72) | K72: =SUMIFS(S$5:S$48,$F$5:$F$48,$A72,$G$5:$G$48,$C72) | L72: =J72-K72 | M72: =SUM(D72,G72,J72) | N72: =SUM(E72,H72,K72) | O72: =M72-N72 | P72: =IF(N72=0,"",M72/N72-1)
A73: TOTAL - all flights | D73: =SUM(M$5:M$48) | E73: =SUM(Q$5:Q$48) | F73: =D73-E73 | G73: =SUM(N$5:N$48) | H73: =SUM(R$5:R$48) | I73: =G73-H73 | J73: =SUM(O$5:O$48) | K73: =SUM(S$5:S$48) | L73: =J73-K73 | M73: =SUM(D73,G73,J73) | N73: =SUM(E73,H73,K73) | O73: =M73-N73 | P73: =IF(N73=0,"",M73/N73-1)
A76: How to read this sheet
A77: Judge the model on the TOTAL row and larger category x time band rows, not single flights | F77: The lookup predicts an average for a category. The benchmark's own per-flight counts swing wildly (0% to 67% of seats across the dataset, and 174 flights in the full schedule show zero eligible passengers), so an individual flight can legitimately differ by +/-40 people even when the day total is within 10%.
...

Sheet Assumptions
A1: Assumptions & Derivation
A2: Base rates (neutral time band) and time-of-day multipliers
A4: Route Group | B4: Route Type | C4: Tier 1 base % | D4: Tier 2 base % | E4: Tier 3 base % | F4: Rationale
A5: Europe & Domestic | B5: Short-haul | C5: 0.002 | D5: 0.011 | E5: 0.15 | F5: No First cabin on short-haul (Club Europe only); Tier 1 limited to status/card holders. Corporate-heavy shorthaul keeps Club/Silver share meaningful.
A6: North America | B6: Long-haul | C6: 0.022 | D6: 0.022 | E6: 0.27 | F6: Highest First and Club World seat share on the network; dense corporate demand from LHR supports elevated Gold/Silver status mix.
A7: Asia & Oceania | B7: Long-haul | C7: 0.027 | D7: 0.024 | E7: 0.29 | F7: Ultra-long-haul widebodies carry the largest First cabins and highest premium load factors; long sector length drives status accumulation.
A8: Middle East & Africa | B8: Long-haul | C8: 0.017 | D8: 0.018 | E8: 0.225 | F8: Mixed leisure/corporate; First offered on limited frequencies, Club World share below NA/Asia, strong transfer-driven Silver base.
A9: South America | B9: Long-haul | C9: 0.014 | D9: 0.015 | E9: 0.205 | F9: Late-evening leisure/business mix; First sold on few frequencies, premium cabin share below network average.
A11: Time-of-day multipliers (business intensity index)
A12: Route Type | B12: Early morning | C12: Midday | D12: Evening | E12: Rationale
A13: Short-haul | B13: 1.3 | C13: 0.75 | D13: 1.1 | E13: Corporate demand concentrates in the 05:00-10:00 and late-afternoon banks; midday departures are leisure-heavy.
A14: Long-haul | B14: 1.15 | C14: 0.9 | D14: 1.1 | E14: Long-haul mix is structurally premium-heavy all day; time-of-day effect is smaller, so multipliers are narrower.
A16: Supporting notes
A17: Base rate construction | B17: Derived from BA access rules: Tier 1 follows the First cabin sell-through plus premium cardholders; Tier 2 follows BA Gold density; Tier 3 follows Club cabin share plus Silver status. Rates are net - status members travelling in a higher cabin are already counted in the higher tier.
A18: Short-haul First | B18: BA short-haul cabins are Club Europe only, so Tier 1 outside First cabins is limited to premier cardholders and Gold Guest List - modelled at 0.2% base.
A19: Load factor assumption | B19: Percentages are applied to boarded passengers, so load factor is already embedded for forecasting; no separate load factor input is required. When verifying against the schedule dataset (seats only), seats are converted to passengers at an assumed 85% load factor.
A20: Validation outcome | B20: These baseline rates were tested against the BA Summer Schedule dataset (10,000 flights): they ran +46% against actual eligible counts on a representative day, overstating long-haul and understating Europe. The Recommended Lookup sheet therefore carries verified rates; the baseline is kept for audit.
A21: Time-of-day effect | B21: Baseline multipliers (1.30 / 0.75 / 1.10) assumed a strong business-vs-leisure swing; the schedule data shows at most 1.1pp variation within a route group across bands (versus 10.6pp between route groups), so recommended band rates are close to 1.00x. Route group is the dominant dimension.
A22: Dataset coverage | B22: 1 Apr - 30 Oct 2025, departures only, regions Europe / North America / Asia / Middle East. Africa and South America are absent - South America recommended rates are judgement, re-based on the verified long-haul pattern; these cells are flagged and should be refreshed when data is available.
A23: Tier 1 is hypothetical | B23: No Concorde Room exists at Terminal 3 today. Tier 1 percentages estimate passengers who would qualify for that level of service, to inform whether a future Tier 1 space is warranted - a potential option, not a confirmed development.
A24: What the model deliberately excludes | B24: Flight numbers, aircraft type, connection traffic and codeshares. This keeps the table portable to any future schedule, including fleet changes not yet defined.
A25: Conservatism | B25: Verified rates are category aggregates (153-2,491 flights per cell) with no growth uplift applied; capacity decisions should still test the +10pc sensitivity case at peak banks.

Sheet Worked Example
A1: Worked Example - Illustrative T3 Operating Day
A2: Lookups are live SUMIFS against the Lookup Table: replace the schedule, results update
A4: Flight | B4: Route Group | C4: Time Band | D4: STD | E4: Pax | F4: Tier 1 % | G4: Tier 2 % | H4: Tier 3 % | I4: Tier 1 pax | J4: Tier 2 pax | K4: Tier 3 pax | L4: Total eligible pax
A5: BA 498 | B5: Europe & Domestic | C5: Early morning | D5: 06:40 | E5: 174 | F5: =SUMIFS('Lookup Table'!$D$5:$D$19,'Lookup Table'!$A$5:$A$19,$B5,'Lookup Table'!$C$5:$C$19,$C5) | G5: =SUMIFS('Lookup Table'!$E$5:$E$19,'Lookup Table'!$A$5:$A$19,$B5,'Lookup Table'!$C$5:$C$19,$C5) | H5: =SUMIFS('Lookup Table'!$F$5:$F$19,'Lookup Table'!$A$5:$A$19,$B5,'Lookup Table'!$C$5:$C$19,$C5) | I5: =ROUND($E5*F5,0) | J5: =ROUND($E5*G5,0) | K5: =ROUND($E5*H5,0) | L5: =SUM(I5:K5)
A6: BA 716 | B6: Europe & Domestic | C6: Early morning | D6: 08:15 | E6: 168 | F6: =SUMIFS('Lookup Table'!$D$5:$D$19,'Lookup Table'!$A$5:$A$19,$B6,'Lookup Table'!$C$5:$C$19,$C6) | G6: =SUMIFS('Lookup Table'!$E$5:$E$19,'Lookup Table'!$A$5:$A$19,$B6,'Lookup Table'!$C$5:$C$19,$C6) | H6: =SUMIFS('Lookup Table'!$F$5:$F$19,'Lookup Table'!$A$5:$A$19,$B6,'Lookup Table'!$C$5:$C$19,$C6) | I6: =ROUND($E6*F6,0) | J6: =ROUND($E6*G6,0) | K6: =ROUND($E6*H6,0) | L6: =SUM(I6:K6)
A7: BA 556 | B7: Europe & Domestic | C7: Midday | D7: 11:30 | E7: 171 | F7: =SUMIFS('Lookup Table'!$D$5:$D$19,'Lookup Table'!$A$5:$A$19,$B7,'Lookup Table'!$C$5:$C$19,$C7) | G7: =SUMIFS('Lookup Table'!$E$5:$E$19,'Lookup Table'!$A$5:$A$19,$B7,'Lookup Table'!$C$5:$C$19,$C7) | H7: =SUMIFS('Lookup Table'!$F$5:$F$19,'Lookup Table'!$A$5:$A$19,$B7,'Lookup Table'!$C$5:$C$19,$C7) | I7: =ROUND($E7*F7,0) | J7: =ROUND($E7*G7,0) | K7: =ROUND($E7*H7,0) | L7: =SUM(I7:K7)
A8: BA 992 | B8: Europe & Domestic | C8: Midday | D8: 14:20 | E8: 176 | F8: =SUMIFS('Lookup Table'!$D$5:$D$19,'Lookup Table'!$A$5:$A$19,$B8,'Lookup Table'!$C$5:$C$19,$C8) | G8: =SUMIFS('Lookup Table'!$E$5:$E$19,'Lookup Table'!$A$5:$A$19,$B8,'Lookup Table'!$C$5:$C$19,$C8) | H8: =SUMIFS('Lookup Table'!$F$5:$F$19,'Lookup Table'!$A$5:$A$19,$B8,'Lookup Table'!$C$5:$C$19,$C8) | I8: =ROUND($E8*F8,0) | J8: =ROUND($E8*G8,0) | K8: =ROUND($E8*H8,0) | L8: =SUM(I8:K8)
A9: BA 486 | B9: Europe & Domestic | C9: Evening | D9: 17:45 | E9: 180 | F9: =SUMIFS('Lookup Table'!$D$5:$D$19,'Lookup Table'!$A$5:$A$19,$B9,'Lookup Table'!$C$5:$C$19,$C9) | G9: =SUMIFS('Lookup Table'!$E$5:$E$19,'Lookup Table'!$A$5:$A$19,$B9,'Lookup Table'!$C$5:$C$19,$C9) | H9: =SUMIFS('Lookup Table'!$F$5:$F$19,'Lookup Table'!$A$5:$A$19,$B9,'Lookup Table'!$C$5:$C$19,$C9) | I9: =ROUND($E9*F9,0) | J9: =ROUND($E9*G9,0) | K9: =ROUND($E9*H9,0) | L9: =SUM(I9:K9)
A10: BA 287 | B10: North America | C10: Early morning | D10: 08:30 | E10: 266 | F10: =SUMIFS('Lookup Table'!$D$5:$D$19,'Lookup Table'!$A$5:$A$19,$B10,'Lookup Table'!$C$5:$C$19,$C10) | G10: =SUMIFS('Lookup Table'!$E$5:$E$19,'Lookup Table'!$A$5:$A$19,$B10,'Lookup Table'!$C$5:$C$19,$C10) | H10: =SUMIFS('Lookup Table'!$F$5:$F$19,'Lookup Table'!$A$5:$A$19,$B10,'Lookup Table'!$C$5:$C$19,$C10) | I10: =ROUND($E10*F10,0) | J10: =ROUND($E10*G10,0) | K10: =ROUND($E10*H10,0) | L10: =SUM(I10:K10)
A11: BA 175 | B11: North America | C11: Evening | D11: 16:15 | E11: 252 | F11: =SUMIFS('Lookup Table'!$D$5:$D$19,'Lookup Table'!$A$5:$A$19,$B11,'Lookup Table'!$C$5:$C$19,$C11) | G11: =SUMIFS('Lookup Table'!$E$5:$E$19,'Lookup Table'!$A$5:$A$19,$B11,'Lookup Table'!$C$5:$C$19,$C11) | H11: =SUMIFS('Lookup Table'!$F$5:$F$19,'Lookup Table'!$A$5:$A$19,$B11,'Lookup Table'!$C$5:$C$19,$C11) | I11: =ROUND($E11*F11,0) | J11: =ROUND($E11*G11,0) | K11: =ROUND($E11*H11,0) | L11: =SUM(I11:K11)
A12: BA 115 | B12: North America | C12: Evening | D12: 19:30 | E12: 297 | F12: =SUMIFS('Lookup Table'!$D$5:$D$19,'Lookup Table'!$A$5:$A$19,$B12,'Lookup Table'!$C$5:$C$19,$C12) | G12: =SUMIFS('Lookup Table'!$E$5:$E$19,'Lookup Table'!$A$5:$A$19,$B12,'Lookup Table'!$C$5:$C$19,$C12) | H12: =SUMIFS('Lookup Table'!$F$5:$F$19,'Lookup Table'!$A$5:$A$19,$B12,'Lookup Table'!$C$5:$C$19,$C12) | I12: =ROUND($E12*F12,0) | J12: =ROUND($E12*G12,0) | K12: =ROUND($E12*H12,0) | L12: =SUM(I12:K12)
A13: BA 011 | B13: Asia & Oceania | C13: Midday | D13: 12:20 | E13: 299 | F13: =SUMIFS('Lookup Table'!$D$5:$D$19,'Lookup Table'!$A$5:$A$19,$B13,'Lookup Table'!$C$5:$C$19,$C13) | G13: =SUMIFS('Lookup Table'!$E$5:$E$19,'Lookup Table'!$A$5:$A$19,$B13,'Lookup Table'!$C$5:$C$19,$C13) | H13: =SUMIFS('Lookup Table'!$F$5:$F$19,'Lookup Table'!$A$5:$A$19,$B13,'Lookup Table'!$C$5:$C$19,$C13) | I13: =ROUND($E13*F13,0) | J13: =ROUND($E13*G13,0) | K13: =ROUND($E13*H13,0) | L13: =SUM(I13:K13)
A14: BA 039 | B14: Asia & Oceania | C14: Evening | D14: 18:45 | E14: 312 | F14: =SUMIFS('Lookup Table'!$D$5:$D$19,'Lookup Table'!$A$5:$A$19,$B14,'Lookup Table'!$C$5:$C$19,$C14) | G14: =SUMIFS('Lookup Table'!$E$5:$E$19,'Lookup Table'!$A$5:$A$19,$B14,'Lookup Table'!$C$5:$C$19,$C14) | H14: =SUMIFS('Lookup Table'!$F$5:$F$19,'Lookup Table'!$A$5:$A$19,$B14,'Lookup Table'!$C$5:$C$19,$C14) | I14: =ROUND($E14*F14,0) | J14: =ROUND($E14*G14,0) | K14: =ROUND($E14*H14,0) | L14: =SUM(I14:K14)
A15: BA 083 | B15: Middle East & Africa | C15: Early morning | D15: 09:45 | E15: 244 | F15: =SUMIFS('Lookup Table'!$D$5:$D$19,'Lookup Table'!$A$5:$A$19,$B15,'Lookup Table'!$C$5:$C$19,$C15) | G15: =SUMIFS('Lookup Table'!$E$5:$E$19,'Lookup Table'!$A$5:$A$19,$B15,'Lookup Table'!$C$5:$C$19,$C15) | H15: =SUMIFS('Lookup Table'!$F$5:$F$19,'Lookup Table'!$A$5:$A$19,$B15,'Lookup Table'!$C$5:$C$19,$C15) | I15: =ROUND($E15*F15,0) | J15: =ROUND($E15*G15,0) | K15: =ROUND($E15*H15,0) | L15: =SUM(I15:K15)
A16: BA 105 | B16: Middle East & Africa | C16: Midday | D16: 10:45 | E16: 271 | F16: =SUMIFS('Lookup Table'!$D$5:$D$19,'Lookup Table'!$A$5:$A$19,$B16,'Lookup Table'!$C$5:$C$19,$C16) | G16: =SUMIFS('Lookup Table'!$E$5:$E$19,'Lookup Table'!$A$5:$A$19,$B16,'Lookup Table'!$C$5:$C$19,$C16) | H16: =SUMIFS('Lookup Table'!$F$5:$F$19,'Lookup Table'!$A$5:$A$19,$B16,'Lookup Table'!$C$5:$C$19,$C16) | I16: =ROUND($E16*F16,0) | J16: =ROUND($E16*G16,0) | K16: =ROUND($E16*H16,0) | L16: =SUM(I16:K16)
... A18: BA 245 | B18: South America | C18: Evening | D18: 22:15 | E18: 263 | F18: =SUMIFS('Lookup Table'!$D$5:$D$19,'Lookup Table'!$A$5:$A$19,$B18,'Lookup Table'!$C$5:$C$19,$C18) | G18: =SUMIFS('Lookup Table'!$E$5:$E$19,'Lookup Table'!$A$5:$A$19,$B18,'Lookup Table'!$C$5:$C$19,$C18) | H18: =SUMIFS('Lookup Table'!$F$5:$F$19,'Lookup Table'!$A$5:$A$19,$B18,'Lookup Table'!$C$5:$C$19,$C18) | I18: =ROUND($E18*F18,0) | J18: =ROUND($E18*G18,0) | K18: =ROUND($E18*H18,0) | L18: =SUM(I18:K18)
A19: TOTAL | E19: =SUM(E5:E18) | I19: =SUM(I5:I18) | J19: =SUM(J5:J18) | K19: =SUM(K5:K18) | L19: =SUM(L5:L18)
A21: Result: | B21: 3,360 passengers across 14 departures -> 925 lounge-eligible (27.5%): Tier 1 56, Tier 2 62, Tier 3 807. Volumes can be compared directly with lounge capacity and opening hours.

Sheet Justification
A1: Written Justification
A2: Why this lookup table is a defensible basis for lounge demand planning
A4: Section | B4: Justification
A5: Objective | B5: BA needs a repeatable way to forecast how many passengers will be eligible for the Concorde Room, First Lounge and Club Lounge at Heathrow T3 under future schedules that are not yet defined. The model forecasts eligibility from stable demand drivers (route group and time of day) rather than from flight numbers or aircraft types, which change with every schedule - then validates itself against real schedule data.
A6: Why these groupings | B6: Eligibility is driven by the premium cabin mix sold on a route and the status mix of the customers who fly it, both strongly correlated with destination. Time of day captures business-versus-leisure skew within a route. Route Group x Time Band gives 15 cells - granular enough to differentiate demand, coarse enough to survive schedule changes. The data confirms this design: across 10,000 summer flights, eligibility spans 14.9-25.5% of passengers, a 10.6pp difference between route groups, while time bands within a group move the rate by at most 1.1pp - route is the dominant dimension and the bands add fine-tuning, not noise.
A7: How the tier rates were derived and then recalibrated | B7: Rates start from BA's published access rules (Tier 1 = First cabin + premier card status; Tier 2 = BA Gold; Tier 3 = Club cabin + Silver; each passenger counted once at their highest tier, so tiers are mutually exclusive and sum to total eligible share). Initial judgement-based baseline rates were then tested against the BA Summer Schedule dataset: on the 18 Jun 2025 sample day the baseline ran +46% vs the dataset's actual eligible counts (it over-weighted long-haul premium and under-weighted Europe). The Recommended Lookup therefore uses verified rates - eligible counts per category divided by boarded passengers (85% load factor assumed, as the dataset lists seats) - bringing the model within +10% of actuals. The baseline table is retained for audit.
A8: The representative sample | B8: 18 June 2025 was selected because it is a full operating day covering all four schedule regions and all three time bands: 44 flights, 10,471 seats, 8,901 passengers at 85% load factor. Every flight is assigned to a category, the recommended percentages are applied via live SUMIFS formulas, and the output is compared with the dataset's TIER1/2/3_ELIGIBLE_PAX. Result: recommended model 1,713 eligible vs 1,557 actual (+10%); hypothetical Tier 1 demand of 15-30 passengers a day.
A9: Defensibility of the result | B9: The lookup is defensible because every cell is traceable: either to a published access rule (assumption baseline) or to a category aggregate over 10,000 flights (verified rates), with 153-2,491 flights behind each verified cell. Counts are mutually exclusive with zero double counting; percentages are per boarded passenger, so load factor is embedded; the model deliberately excludes flight numbers and aircraft types so it remains valid under any future schedule or fleet plan. Tier 1 is presented as a hypothetical Tier 1/Concorde-style space at T3 - no Concorde Room exists there today - sized at roughly 15-30 passengers a day to inform whether such a space is warranted.
A10: Reuse with future schedules | B10: To apply the model to any future schedule, planners classify each flight by route group and departure time band, multiply expected passengers by the recommended percentages, and sum - by day, by peak bank or by lounge. No flight-level data beyond destination, STD and a passenger forecast is required, so the table works for new routes, frequency changes, aircraft swaps or retimed departures. Volumes can then be tested against lounge capacity, opening hours and peak-hour concurrency to target investment.
A11: Limitations and next step | B11: The model estimates eligibility, not usage (eligible passengers may not visit; connecting passengers and other airlines' lounge users are excluded). The schedule dataset covers one summer season (Apr-Oct 2025) with seats rather than passengers, so 85% load factor is assumed; South America/Africa are not in the dataset. Next step: refresh the category aggregation each schedule season and back-test against actual lounge access scans - only the rate cells change, so historical comparisons remain valid.
